"GET /about/ HTTP/1.1" 500 59
"GET /favicon.ico HTTP/1.1" 500 59
"GET / HTTP/1.1" 500 59
"GET /favicon.ico HTTP/1.1" 500 59
Internal Server Error: /
Traceback (most recent call last):
  File "/data/data/com.termux/files/usr/lib/python3.11/site-packages/django/db/backends/utils.py", line 84, in _execute
    return self.cursor.execute(sql, params)
           ^^^^^^^^^^^^^^^^^^^^^^^^^^^^^^^^
  File "/data/data/com.termux/files/usr/lib/python3.11/site-packages/django/db/backends/sqlite3/base.py", line 423, in execute
    return Database.Cursor.execute(self, query, params)
           ^^^^^^^^^^^^^^^^^^^^^^^^^^^^^^^^^^^^^^^^^^^^
sqlite3.OperationalError: no such table: app_department

The above exception was the direct cause of the following exception:

Traceback (most recent call last):
  File "/data/data/com.termux/files/usr/lib/python3.11/site-packages/django/core/handlers/exception.py", line 47, in inner
    response = get_response(request)
               ^^^^^^^^^^^^^^^^^^^^^
  File "/data/data/com.termux/files/usr/lib/python3.11/site-packages/django/core/handlers/base.py", line 181, in _get_response
    response = wrapped_callback(request, *callback_args, **callback_kwargs)
               ^^^^^^^^^^^^^^^^^^^^^^^^^^^^^^^^^^^^^^^^^^^^^^^^^^^^^^^^^^^^
  File "/storage/emulated/0/epols/app/views.py", line 13, in index
    context['departments_count'] = Department.objects.count()
                                   ^^^^^^^^^^^^^^^^^^^^^^^^^^
  File "/data/data/com.termux/files/usr/lib/python3.11/site-packages/django/db/models/manager.py", line 85, in manager_method
    return getattr(self.get_queryset(), name)(*args, **kwargs)
           ^^^^^^^^^^^^^^^^^^^^^^^^^^^^^^^^^^^^^^^^^^^^^^^^^^^
  File "/data/data/com.termux/files/usr/lib/python3.11/site-packages/django/db/models/query.py", line 412, in count
    return self.query.get_count(using=self.db)
           ^^^^^^^^^^^^^^^^^^^^^^^^^^^^^^^^^^^
  File "/data/data/com.termux/files/usr/lib/python3.11/site-packages/django/db/models/sql/query.py", line 526, in get_count
    number = obj.get_aggregation(using, ['__count'])['__count']
             ^^^^^^^^^^^^^^^^^^^^^^^^^^^^^^^^^^^^^^^
  File "/data/data/com.termux/files/usr/lib/python3.11/site-packages/django/db/models/sql/query.py", line 511, in get_aggregation
    result = compiler.execute_sql(SINGLE)
             ^^^^^^^^^^^^^^^^^^^^^^^^^^^^
  File "/data/data/com.termux/files/usr/lib/python3.11/site-packages/django/db/models/sql/compiler.py", line 1169, in execute_sql
    cursor.execute(sql, params)
  File "/data/data/com.termux/files/usr/lib/python3.11/site-packages/django/db/backends/utils.py", line 98, in execute
    return super().execute(sql, params)
           ^^^^^^^^^^^^^^^^^^^^^^^^^^^^
  File "/data/data/com.termux/files/usr/lib/python3.11/site-packages/django/db/backends/utils.py", line 66, in execute
    return self._execute_with_wrappers(sql, params, many=False, executor=self._execute)
           ^^^^^^^^^^^^^^^^^^^^^^^^^^^^^^^^^^^^^^^^^^^^^^^^^^^^^^^^^^^^^^^^^^^^^^^^^^^^
  File "/data/data/com.termux/files/usr/lib/python3.11/site-packages/django/db/backends/utils.py", line 75, in _execute_with_wrappers
    return executor(sql, params, many, context)
           ^^^^^^^^^^^^^^^^^^^^^^^^^^^^^^^^^^^^
  File "/data/data/com.termux/files/usr/lib/python3.11/site-packages/django/db/backends/utils.py", line 79, in _execute
    with self.db.wrap_database_errors:
  File "/data/data/com.termux/files/usr/lib/python3.11/site-packages/django/db/utils.py", line 90, in __exit__
    raise dj_exc_value.with_traceback(traceback) from exc_value
  File "/data/data/com.termux/files/usr/lib/python3.11/site-packages/django/db/backends/utils.py", line 84, in _execute
    return self.cursor.execute(sql, params)
           ^^^^^^^^^^^^^^^^^^^^^^^^^^^^^^^^
  File "/data/data/com.termux/files/usr/lib/python3.11/site-packages/django/db/backends/sqlite3/base.py", line 423, in execute
    return Database.Cursor.execute(self, query, params)
           ^^^^^^^^^^^^^^^^^^^^^^^^^^^^^^^^^^^^^^^^^^^^
django.db.utils.OperationalError: no such table: app_department
"GET / HTTP/1.1" 500 126461
Internal Server Error: /
Traceback (most recent call last):
  File "/data/data/com.termux/files/usr/lib/python3.11/site-packages/django/core/handlers/exception.py", line 47, in inner
    response = get_response(request)
               ^^^^^^^^^^^^^^^^^^^^^
  File "/data/data/com.termux/files/usr/lib/python3.11/site-packages/django/core/handlers/base.py", line 181, in _get_response
    response = wrapped_callback(request, *callback_args, **callback_kwargs)
               ^^^^^^^^^^^^^^^^^^^^^^^^^^^^^^^^^^^^^^^^^^^^^^^^^^^^^^^^^^^^
  File "/storage/emulated/0/epols/app/views.py", line 17, in index
    return render(request, 'app/index.html', context)
           ^^^^^^^^^^^^^^^^^^^^^^^^^^^^^^^^^^^^^^^^^^
  File "/data/data/com.termux/files/usr/lib/python3.11/site-packages/django/shortcuts.py", line 19, in render
    content = loader.render_to_string(template_name, context, request, using=using)
              ^^^^^^^^^^^^^^^^^^^^^^^^^^^^^^^^^^^^^^^^^^^^^^^^^^^^^^^^^^^^^^^^^^^^^
  File "/data/data/com.termux/files/usr/lib/python3.11/site-packages/django/template/loader.py", line 62, in render_to_string
    return template.render(context, request)
           ^^^^^^^^^^^^^^^^^^^^^^^^^^^^^^^^^
  File "/data/data/com.termux/files/usr/lib/python3.11/site-packages/django/template/backends/django.py", line 61, in render
    return self.template.render(context)
           ^^^^^^^^^^^^^^^^^^^^^^^^^^^^^
  File "/data/data/com.termux/files/usr/lib/python3.11/site-packages/django/template/base.py", line 168, in render
    with context.bind_template(self):
  File "/data/data/com.termux/files/usr/lib/python3.11/contextlib.py", line 137, in __enter__
    return next(self.gen)
           ^^^^^^^^^^^^^^
  File "/data/data/com.termux/files/usr/lib/python3.11/site-packages/django/template/context.py", line 240, in bind_template
    processors = (template.engine.template_context_processors +
                  ^^^^^^^^^^^^^^^^^^^^^^^^^^^^^^^^^^^^^^^^^^^
  File "/data/data/com.termux/files/usr/lib/python3.11/site-packages/django/utils/functional.py", line 48, in __get__
    res = instance.__dict__[self.name] = self.func(instance)
                                         ^^^^^^^^^^^^^^^^^^^
  File "/data/data/com.termux/files/usr/lib/python3.11/site-packages/django/template/engine.py", line 85, in template_context_processors
    return tuple(import_string(path) for path in context_processors)
           ^^^^^^^^^^^^^^^^^^^^^^^^^^^^^^^^^^^^^^^^^^^^^^^^^^^^^^^^^
  File "/data/data/com.termux/files/usr/lib/python3.11/site-packages/django/template/engine.py", line 85, in <genexpr>
    return tuple(import_string(path) for path in context_processors)
                 ^^^^^^^^^^^^^^^^^^^
  File "/data/data/com.termux/files/usr/lib/python3.11/site-packages/django/utils/module_loading.py", line 17, in import_string
    module = import_module(module_path)
             ^^^^^^^^^^^^^^^^^^^^^^^^^^
  File "/data/data/com.termux/files/usr/lib/python3.11/importlib/__init__.py", line 126, in import_module
    return _bootstrap._gcd_import(name[level:], package, level)
           ^^^^^^^^^^^^^^^^^^^^^^^^^^^^^^^^^^^^^^^^^^^^^^^^^^^^
  File "<frozen importlib._bootstrap>", line 1204, in _gcd_import
  File "<frozen importlib._bootstrap>", line 1176, in _find_and_load
  File "<frozen importlib._bootstrap>", line 1147, in _find_and_load_unlocked
  File "<frozen importlib._bootstrap>", line 690, in _load_unlocked
  File "<frozen importlib._bootstrap_external>", line 936, in exec_module
  File "<frozen importlib._bootstrap_external>", line 1074, in get_code
  File "<frozen importlib._bootstrap_external>", line 1004, in source_to_code
  File "<frozen importlib._bootstrap>", line 241, in _call_with_frames_removed
  File "/storage/emulated/0/epols/core/contexts.py", line 6
    "pr_big_logo": "" 
                 ^
SyntaxError: invalid syntax
"GET / HTTP/1.1" 500 126903
Internal Server Error: /
Traceback (most recent call last):
  File "/data/data/com.termux/files/usr/lib/python3.11/site-packages/django/core/handlers/exception.py", line 47, in inner
    response = get_response(request)
               ^^^^^^^^^^^^^^^^^^^^^
  File "/data/data/com.termux/files/usr/lib/python3.11/site-packages/django/core/handlers/base.py", line 181, in _get_response
    response = wrapped_callback(request, *callback_args, **callback_kwargs)
               ^^^^^^^^^^^^^^^^^^^^^^^^^^^^^^^^^^^^^^^^^^^^^^^^^^^^^^^^^^^^
  File "/storage/emulated/0/epols/app/views.py", line 17, in index
    return render(request, 'app/index.html', context)
           ^^^^^^^^^^^^^^^^^^^^^^^^^^^^^^^^^^^^^^^^^^
  File "/data/data/com.termux/files/usr/lib/python3.11/site-packages/django/shortcuts.py", line 19, in render
    content = loader.render_to_string(template_name, context, request, using=using)
              ^^^^^^^^^^^^^^^^^^^^^^^^^^^^^^^^^^^^^^^^^^^^^^^^^^^^^^^^^^^^^^^^^^^^^
  File "/data/data/com.termux/files/usr/lib/python3.11/site-packages/django/template/loader.py", line 62, in render_to_string
    return template.render(context, request)
           ^^^^^^^^^^^^^^^^^^^^^^^^^^^^^^^^^
  File "/data/data/com.termux/files/usr/lib/python3.11/site-packages/django/template/backends/django.py", line 61, in render
    return self.template.render(context)
           ^^^^^^^^^^^^^^^^^^^^^^^^^^^^^
  File "/data/data/com.termux/files/usr/lib/python3.11/site-packages/django/template/base.py", line 168, in render
    with context.bind_template(self):
  File "/data/data/com.termux/files/usr/lib/python3.11/contextlib.py", line 137, in __enter__
    return next(self.gen)
           ^^^^^^^^^^^^^^
  File "/data/data/com.termux/files/usr/lib/python3.11/site-packages/django/template/context.py", line 240, in bind_template
    processors = (template.engine.template_context_processors +
                  ^^^^^^^^^^^^^^^^^^^^^^^^^^^^^^^^^^^^^^^^^^^
  File "/data/data/com.termux/files/usr/lib/python3.11/site-packages/django/utils/functional.py", line 48, in __get__
    res = instance.__dict__[self.name] = self.func(instance)
                                         ^^^^^^^^^^^^^^^^^^^
  File "/data/data/com.termux/files/usr/lib/python3.11/site-packages/django/template/engine.py", line 85, in template_context_processors
    return tuple(import_string(path) for path in context_processors)
           ^^^^^^^^^^^^^^^^^^^^^^^^^^^^^^^^^^^^^^^^^^^^^^^^^^^^^^^^^
  File "/data/data/com.termux/files/usr/lib/python3.11/site-packages/django/template/engine.py", line 85, in <genexpr>
    return tuple(import_string(path) for path in context_processors)
                 ^^^^^^^^^^^^^^^^^^^
  File "/data/data/com.termux/files/usr/lib/python3.11/site-packages/django/utils/module_loading.py", line 17, in import_string
    module = import_module(module_path)
             ^^^^^^^^^^^^^^^^^^^^^^^^^^
  File "/data/data/com.termux/files/usr/lib/python3.11/importlib/__init__.py", line 126, in import_module
    return _bootstrap._gcd_import(name[level:], package, level)
           ^^^^^^^^^^^^^^^^^^^^^^^^^^^^^^^^^^^^^^^^^^^^^^^^^^^^
  File "<frozen importlib._bootstrap>", line 1204, in _gcd_import
  File "<frozen importlib._bootstrap>", line 1176, in _find_and_load
  File "<frozen importlib._bootstrap>", line 1147, in _find_and_load_unlocked
  File "<frozen importlib._bootstrap>", line 690, in _load_unlocked
  File "<frozen importlib._bootstrap_external>", line 936, in exec_module
  File "<frozen importlib._bootstrap_external>", line 1074, in get_code
  File "<frozen importlib._bootstrap_external>", line 1004, in source_to_code
  File "<frozen importlib._bootstrap>", line 241, in _call_with_frames_removed
  File "/storage/emulated/0/epols/core/contexts.py", line 8
    def project_info:
                    ^
SyntaxError: expected '('
"GET / HTTP/1.1" 500 127058
Internal Server Error: /
Traceback (most recent call last):
  File "/data/data/com.termux/files/usr/lib/python3.11/site-packages/django/core/handlers/exception.py", line 47, in inner
    response = get_response(request)
               ^^^^^^^^^^^^^^^^^^^^^
  File "/data/data/com.termux/files/usr/lib/python3.11/site-packages/django/core/handlers/base.py", line 181, in _get_response
    response = wrapped_callback(request, *callback_args, **callback_kwargs)
               ^^^^^^^^^^^^^^^^^^^^^^^^^^^^^^^^^^^^^^^^^^^^^^^^^^^^^^^^^^^^
  File "/storage/emulated/0/epols/app/views.py", line 17, in index
    return render(request, 'app/index.html', context)
           ^^^^^^^^^^^^^^^^^^^^^^^^^^^^^^^^^^^^^^^^^^
  File "/data/data/com.termux/files/usr/lib/python3.11/site-packages/django/shortcuts.py", line 19, in render
    content = loader.render_to_string(template_name, context, request, using=using)
              ^^^^^^^^^^^^^^^^^^^^^^^^^^^^^^^^^^^^^^^^^^^^^^^^^^^^^^^^^^^^^^^^^^^^^
  File "/data/data/com.termux/files/usr/lib/python3.11/site-packages/django/template/loader.py", line 62, in render_to_string
    return template.render(context, request)
           ^^^^^^^^^^^^^^^^^^^^^^^^^^^^^^^^^
  File "/data/data/com.termux/files/usr/lib/python3.11/site-packages/django/template/backends/django.py", line 61, in render
    return self.template.render(context)
           ^^^^^^^^^^^^^^^^^^^^^^^^^^^^^
  File "/data/data/com.termux/files/usr/lib/python3.11/site-packages/django/template/base.py", line 168, in render
    with context.bind_template(self):
  File "/data/data/com.termux/files/usr/lib/python3.11/contextlib.py", line 137, in __enter__
    return next(self.gen)
           ^^^^^^^^^^^^^^
  File "/data/data/com.termux/files/usr/lib/python3.11/site-packages/django/template/context.py", line 244, in bind_template
    updates.update(processor(self.request))
                   ^^^^^^^^^^^^^^^^^^^^^^^
TypeError: project_info() takes 0 positional arguments but 1 was given
"GET / HTTP/1.1" 500 90785
Internal Server Error: /timetables/
Traceback (most recent call last):
  File "/data/data/com.termux/files/usr/lib/python3.11/site-packages/django/core/handlers/exception.py", line 47, in inner
    response = get_response(request)
               ^^^^^^^^^^^^^^^^^^^^^
  File "/data/data/com.termux/files/usr/lib/python3.11/site-packages/django/core/handlers/base.py", line 181, in _get_response
    response = wrapped_callback(request, *callback_args, **callback_kwargs)
               ^^^^^^^^^^^^^^^^^^^^^^^^^^^^^^^^^^^^^^^^^^^^^^^^^^^^^^^^^^^^
  File "/storage/emulated/0/epols/app/views.py", line 107, in timetable_view
    timetable = TimeTable.objects.get(department__id = int(department), level = int(level))
                ^^^^^^^^^^^^^^^^^^^^^^^^^^^^^^^^^^^^^^^^^^^^^^^^^^^^^^^^^^^^^^^^^^^^^^^^^^^
  File "/data/data/com.termux/files/usr/lib/python3.11/site-packages/django/db/models/manager.py", line 85, in manager_method
    return getattr(self.get_queryset(), name)(*args, **kwargs)
           ^^^^^^^^^^^^^^^^^^^^^^^^^^^^^^^^^^^^^^^^^^^^^^^^^^^
  File "/data/data/com.termux/files/usr/lib/python3.11/site-packages/django/db/models/query.py", line 435, in get
    raise self.model.DoesNotExist(
app.models.TimeTable.DoesNotExist: TimeTable matching query does not exist.
"GET /timetables/?department=6&level=200 HTTP/1.1" 500 73989
You're accessing the development server over HTTPS, but it only supports HTTP.

You're accessing the development server over HTTPS, but it only supports HTTP.

You're accessing the development server over HTTPS, but it only supports HTTP.

You're accessing the development server over HTTPS, but it only supports HTTP.

